An exception occurred during task execution. To see the full traceback, use -vvv. The error was: 1 out of 1 hunks failed--saving rejects to ext/intl/config.m4.rej
failed: [provisioner13] (item=patch_php_icu75.patch) => {"ansible_loop_var": "item", "changed": false, "item": "patch_php_icu75.patch", "msg": "1 out of 1 hunks failed--saving rejects to -\n@@ -48754,7 +48754,7 @@\n   fi\n \n \n-  ax_cxx_compile_alternatives=\"11 0x\"  ax_cxx_compile_cxx11_required=truednl\n+  ax_cxx_compile_alternatives=\"17 11 0x\"  ax_cxx_compile_cxx11_required=truednl\n   ac_ext=cpp\n ac_cpp='$CXXCPP $CPPFLAGS'\n ac_compile='$CXX -c $CXXFLAGS $CPPFLAGS conftest.$ac_ext >&5'\n1 out of 1 hunks failed--saving rejects to ext/intl/config.m4.rej\n"}
